<mujoco>
    <option timestep=".001">
        <flag energy="enable" contact="enable" override="enable"/>
    </option>

    <default>
        <default class="hole_geom">
            <geom xyaxes="1 0 0 0 1 0" rgba="0 0 1 0.2"/>
        </default>
        <site size="0.0002" />
        <geom friction="10000" />
    </default>

    <visual>
        <global offwidth="960" offheight="720"/>
    </visual>

    <asset>
        <mesh name="peg1" file="../asset/circle/circle_peg_A/Body1.stl" />
        <mesh name="peg2" file="../asset/circle/circle_peg_A/Body2.stl" />
        <mesh name="peg3" file="../asset/circle/circle_peg_A/Body3.stl" />
        
        <mesh name="hole1" file="../asset/circle/circle_hole_A/Body1.stl" />
        <mesh name="hole2" file="../asset/circle/circle_hole_A/Body2.stl" />
        <mesh name="hole3" file="../asset/circle/circle_hole_A/Body3.stl" />
        <mesh name="hole4" file="../asset/circle/circle_hole_A/Body4.stl" />
        <mesh name="hole5" file="../asset/circle/circle_hole_A/Body5.stl" />
        <mesh name="hole6" file="../asset/circle/circle_hole_A/Body6.stl" />
        <mesh name="hole7" file="../asset/circle/circle_hole_A/Body7.stl" />
        <mesh name="hole8" file="../asset/circle/circle_hole_A/Body8.stl" />
        <mesh name="hole9" file="../asset/circle/circle_hole_A/Body9.stl" />
        <mesh name="hole10" file="../asset/circle/circle_hole_A/Body10.stl" />
        <mesh name="hole11" file="../asset/circle/circle_hole_A/Body11.stl" />
        <mesh name="hole12" file="../asset/circle/circle_hole_A/Body12.stl" />
        <mesh name="hole13" file="../asset/circle/circle_hole_A/Body13.stl" />
        <mesh name="hole14" file="../asset/circle/circle_hole_A/Body14.stl" />
        <mesh name="hole15" file="../asset/circle/circle_hole_A/Body15.stl" />
        <mesh name="hole16" file="../asset/circle/circle_hole_A/Body16.stl" />
        <mesh name="hole17" file="../asset/circle/circle_hole_A/Body17.stl" />
        <mesh name="hole18" file="../asset/circle/circle_hole_A/Body18.stl" />
        <mesh name="hole19" file="../asset/circle/circle_hole_A/Body19.stl" />
        <mesh name="hole20" file="../asset/circle/circle_hole_A/Body20.stl" />
        <mesh name="hole21" file="../asset/circle/circle_hole_A/Body21.stl" />
        <mesh name="hole22" file="../asset/circle/circle_hole_A/Body22.stl" />
        <mesh name="hole23" file="../asset/circle/circle_hole_A/Body23.stl" />
        <mesh name="hole24" file="../asset/circle/circle_hole_A/Body24.stl" />
        <mesh name="hole25" file="../asset/circle/circle_hole_A/Body25.stl" />
        <mesh name="hole26" file="../asset/circle/circle_hole_A/Body26.stl" />
        <mesh name="hole27" file="../asset/circle/circle_hole_A/Body27.stl" />
        <mesh name="hole28" file="../asset/circle/circle_hole_A/Body28.stl" />
        <mesh name="hole29" file="../asset/circle/circle_hole_A/Body29.stl" />
        <mesh name="hole30" file="../asset/circle/circle_hole_A/Body30.stl" />
        <mesh name="hole31" file="../asset/circle/circle_hole_A/Body31.stl" />
        <mesh name="hole32" file="../asset/circle/circle_hole_A/Body32.stl" />
        <mesh name="hole33" file="../asset/circle/circle_hole_A/Body33.stl" />
        <mesh name="hole34" file="../asset/circle/circle_hole_A/Body34.stl" />
        <mesh name="hole35" file="../asset/circle/circle_hole_A/Body35.stl" />
        <mesh name="hole36" file="../asset/circle/circle_hole_A/Body36.stl" />
        <mesh name="hole37" file="../asset/circle/circle_hole_A/Body37.stl" />
        <mesh name="hole38" file="../asset/circle/circle_hole_A/Body38.stl" />
        <mesh name="hole39" file="../asset/circle/circle_hole_A/Body39.stl" />
        <mesh name="hole40" file="../asset/circle/circle_hole_A/Body40.stl" />
        <mesh name="hole41" file="../asset/circle/circle_hole_A/Body41.stl" />
        <mesh name="hole42" file="../asset/circle/circle_hole_A/Body42.stl" />
        <mesh name="hole43" file="../asset/circle/circle_hole_A/Body43.stl" />
        <mesh name="hole44" file="../asset/circle/circle_hole_A/Body44.stl" />
        <mesh name="hole45" file="../asset/circle/circle_hole_A/Body45.stl" />
        <mesh name="hole46" file="../asset/circle/circle_hole_A/Body46.stl" />
        <mesh name="hole47" file="../asset/circle/circle_hole_A/Body47.stl" />
        <mesh name="hole48" file="../asset/circle/circle_hole_A/Body48.stl" />
        <mesh name="hole49" file="../asset/circle/circle_hole_A/Body49.stl" />
        <mesh name="hole50" file="../asset/circle/circle_hole_A/Body50.stl" />
        <mesh name="hole51" file="../asset/circle/circle_hole_A/Body51.stl" />
        <mesh name="hole52" file="../asset/circle/circle_hole_A/Body52.stl" />
        <mesh name="hole53" file="../asset/circle/circle_hole_A/Body53.stl" />
        <mesh name="hole54" file="../asset/circle/circle_hole_A/Body54.stl" />
        <mesh name="hole55" file="../asset/circle/circle_hole_A/Body55.stl" />
        <mesh name="hole56" file="../asset/circle/circle_hole_A/Body56.stl" />
        <mesh name="hole57" file="../asset/circle/circle_hole_A/Body57.stl" />
        <mesh name="hole58" file="../asset/circle/circle_hole_A/Body58.stl" />
        <mesh name="hole59" file="../asset/circle/circle_hole_A/Body59.stl" />
        <mesh name="hole60" file="../asset/circle/circle_hole_A/Body60.stl" />
        <mesh name="hole61" file="../asset/circle/circle_hole_A/Body61.stl" />
        <mesh name="hole62" file="../asset/circle/circle_hole_A/Body62.stl" />
        <mesh name="hole63" file="../asset/circle/circle_hole_A/Body63.stl" />
        <mesh name="hole64" file="../asset/circle/circle_hole_A/Body64.stl" />
        <mesh name="hole65" file="../asset/circle/circle_hole_A/Body65.stl" />
        <mesh name="hole66" file="../asset/circle/circle_hole_A/Body66.stl" />
        <mesh name="hole67" file="../asset/circle/circle_hole_A/Body67.stl" />
        <mesh name="hole68" file="../asset/circle/circle_hole_A/Body68.stl" />
        <mesh name="hole69" file="../asset/circle/circle_hole_A/Body69.stl" />
        <mesh name="hole70" file="../asset/circle/circle_hole_A/Body70.stl" />
        <mesh name="hole71" file="../asset/circle/circle_hole_A/Body71.stl" />
        <mesh name="hole72" file="../asset/circle/circle_hole_A/Body72.stl" />
        <mesh name="hole73" file="../asset/circle/circle_hole_A/Body73.stl" />


    </asset>

    <worldbody>
        <site name="world" pos="0 0 0" size="0.0001" />
        
        <light name="top-light" pos="0.0 0.0 0.5" mode="targetbodycom" target="peg" castshadow="false" ambient=".8 .8 .8" />

        <body name="hole" pos="0 0 0">

            <camera name="track" mode="track" pos="-0.050 -0.050 0.025" euler="60 -45 -30" fovy="69.4"/>

            <inertial pos="0 0 0" mass="0.1" diaginertia="0.1 0.1 0.1" />

            <geom type="mesh" mesh="hole1" xyaxes="1 0 0 0 1 0" rgba="0 0 1 0.2"/>
            <geom type="mesh" mesh="hole2" xyaxes="1 0 0 0 1 0" rgba="0 0 1 0.2"/>
            <geom type="mesh" mesh="hole3" xyaxes="1 0 0 0 1 0" rgba="0 0 1 0.2"/>
            <geom type="mesh" mesh="hole4" xyaxes="1 0 0 0 1 0" rgba="0 0 1 0.2"/>
            <geom type="mesh" mesh="hole5" xyaxes="1 0 0 0 1 0" rgba="0 0 1 0.2"/>
            <geom type="mesh" mesh="hole6" xyaxes="1 0 0 0 1 0" rgba="0 0 1 0.2"/>
            <geom type="mesh" mesh="hole7" xyaxes="1 0 0 0 1 0" rgba="0 0 1 0.2"/>
            <geom type="mesh" mesh="hole8" xyaxes="1 0 0 0 1 0" rgba="0 0 1 0.2"/>
            <geom type="mesh" mesh="hole9" xyaxes="1 0 0 0 1 0" rgba="0 0 1 0.2"/>
            <geom type="mesh" mesh="hole10" xyaxes="1 0 0 0 1 0" rgba="0 0 1 0.2"/>
            <geom type="mesh" mesh="hole11" xyaxes="1 0 0 0 1 0" rgba="0 0 1 0.2"/>
            <geom type="mesh" mesh="hole12" xyaxes="1 0 0 0 1 0" rgba="0 0 1 0.2"/>
            <geom type="mesh" mesh="hole13" xyaxes="1 0 0 0 1 0" rgba="0 0 1 0.2"/>
            <geom type="mesh" mesh="hole14" xyaxes="1 0 0 0 1 0" rgba="0 0 1 0.2"/>
            <geom type="mesh" mesh="hole15" xyaxes="1 0 0 0 1 0" rgba="0 0 1 0.2"/>
            <geom type="mesh" mesh="hole16" xyaxes="1 0 0 0 1 0" rgba="0 0 1 0.2"/>
            <geom type="mesh" mesh="hole17" xyaxes="1 0 0 0 1 0" rgba="0 0 1 0.2"/>
            <geom type="mesh" mesh="hole18" xyaxes="1 0 0 0 1 0" rgba="0 0 1 0.2"/>
            <geom type="mesh" mesh="hole19" xyaxes="1 0 0 0 1 0" rgba="0 0 1 0.2"/>
            <geom type="mesh" mesh="hole20" xyaxes="1 0 0 0 1 0" rgba="0 0 1 0.2"/>
            <geom type="mesh" mesh="hole21" xyaxes="1 0 0 0 1 0" rgba="0 0 1 0.2"/>
            <geom type="mesh" mesh="hole22" xyaxes="1 0 0 0 1 0" rgba="0 0 1 0.2"/>
            <geom type="mesh" mesh="hole23" xyaxes="1 0 0 0 1 0" rgba="0 0 1 0.2"/>
            <geom type="mesh" mesh="hole24" xyaxes="1 0 0 0 1 0" rgba="0 0 1 0.2"/>
            <geom type="mesh" mesh="hole25" xyaxes="1 0 0 0 1 0" rgba="0 0 1 0.2"/>
            <geom type="mesh" mesh="hole26" xyaxes="1 0 0 0 1 0" rgba="0 0 1 0.2"/>
            <geom type="mesh" mesh="hole27" xyaxes="1 0 0 0 1 0" rgba="0 0 1 0.2"/>
            <geom type="mesh" mesh="hole28" xyaxes="1 0 0 0 1 0" rgba="0 0 1 0.2"/>
            <geom type="mesh" mesh="hole29" xyaxes="1 0 0 0 1 0" rgba="0 0 1 0.2"/>
            <geom type="mesh" mesh="hole30" xyaxes="1 0 0 0 1 0" rgba="0 0 1 0.2"/>
            <geom type="mesh" mesh="hole31" xyaxes="1 0 0 0 1 0" rgba="0 0 1 0.2"/>
            <geom type="mesh" mesh="hole32" xyaxes="1 0 0 0 1 0" rgba="0 0 1 0.2"/>
            <geom type="mesh" mesh="hole33" xyaxes="1 0 0 0 1 0" rgba="0 0 1 0.2"/>
            <geom type="mesh" mesh="hole34" xyaxes="1 0 0 0 1 0" rgba="0 0 1 0.2"/>
            <geom type="mesh" mesh="hole35" xyaxes="1 0 0 0 1 0" rgba="0 0 1 0.2"/>
            <geom type="mesh" mesh="hole36" xyaxes="1 0 0 0 1 0" rgba="0 0 1 0.2"/>
            <geom type="mesh" mesh="hole37" xyaxes="1 0 0 0 1 0" rgba="0 0 1 0.2"/>
            <geom type="mesh" mesh="hole38" xyaxes="1 0 0 0 1 0" rgba="0 0 1 0.2"/>
            <geom type="mesh" mesh="hole39" xyaxes="1 0 0 0 1 0" rgba="0 0 1 0.2"/>
            <geom type="mesh" mesh="hole40" xyaxes="1 0 0 0 1 0" rgba="0 0 1 0.2"/>
            <geom type="mesh" mesh="hole41" xyaxes="1 0 0 0 1 0" rgba="0 0 1 0.2"/>
            <geom type="mesh" mesh="hole42" xyaxes="1 0 0 0 1 0" rgba="0 0 1 0.2"/>
            <geom type="mesh" mesh="hole43" xyaxes="1 0 0 0 1 0" rgba="0 0 1 0.2"/>
            <geom type="mesh" mesh="hole44" xyaxes="1 0 0 0 1 0" rgba="0 0 1 0.2"/>
            <geom type="mesh" mesh="hole45" xyaxes="1 0 0 0 1 0" rgba="0 0 1 0.2"/>
            <geom type="mesh" mesh="hole46" xyaxes="1 0 0 0 1 0" rgba="0 0 1 0.2"/>
            <geom type="mesh" mesh="hole47" xyaxes="1 0 0 0 1 0" rgba="0 0 1 0.2"/>
            <geom type="mesh" mesh="hole48" xyaxes="1 0 0 0 1 0" rgba="0 0 1 0.2"/>
            <geom type="mesh" mesh="hole49" xyaxes="1 0 0 0 1 0" rgba="0 0 1 0.2"/>
            <geom type="mesh" mesh="hole50" xyaxes="1 0 0 0 1 0" rgba="0 0 1 0.2"/>
            <geom type="mesh" mesh="hole51" xyaxes="1 0 0 0 1 0" rgba="0 0 1 0.2"/>
            <geom type="mesh" mesh="hole52" xyaxes="1 0 0 0 1 0" rgba="0 0 1 0.2"/>
            <geom type="mesh" mesh="hole53" xyaxes="1 0 0 0 1 0" rgba="0 0 1 0.2"/>
            <geom type="mesh" mesh="hole54" xyaxes="1 0 0 0 1 0" rgba="0 0 1 0.2"/>
            <geom type="mesh" mesh="hole55" xyaxes="1 0 0 0 1 0" rgba="0 0 1 0.2"/>
            <geom type="mesh" mesh="hole56" xyaxes="1 0 0 0 1 0" rgba="0 0 1 0.2"/>
            <geom type="mesh" mesh="hole57" xyaxes="1 0 0 0 1 0" rgba="0 0 1 0.2"/>
            <geom type="mesh" mesh="hole58" xyaxes="1 0 0 0 1 0" rgba="0 0 1 0.2"/>
            <geom type="mesh" mesh="hole59" xyaxes="1 0 0 0 1 0" rgba="0 0 1 0.2"/>
            <geom type="mesh" mesh="hole60" xyaxes="1 0 0 0 1 0" rgba="0 0 1 0.2"/>
            <geom type="mesh" mesh="hole61" xyaxes="1 0 0 0 1 0" rgba="0 0 1 0.2"/>
            <geom type="mesh" mesh="hole62" xyaxes="1 0 0 0 1 0" rgba="0 0 1 0.2"/>
            <geom type="mesh" mesh="hole63" xyaxes="1 0 0 0 1 0" rgba="0 0 1 0.2"/>
            <geom type="mesh" mesh="hole64" xyaxes="1 0 0 0 1 0" rgba="0 0 1 0.2"/>
            <geom type="mesh" mesh="hole65" xyaxes="1 0 0 0 1 0" rgba="0 0 1 0.2"/>
            <geom type="mesh" mesh="hole66" xyaxes="1 0 0 0 1 0" rgba="0 0 1 0.2"/>
            <geom type="mesh" mesh="hole67" xyaxes="1 0 0 0 1 0" rgba="0 0 1 0.2"/>
            <geom type="mesh" mesh="hole68" xyaxes="1 0 0 0 1 0" rgba="0 0 1 0.2"/>
            <geom type="mesh" mesh="hole69" xyaxes="1 0 0 0 1 0" rgba="0 0 1 0.2"/>
            <geom type="mesh" mesh="hole70" xyaxes="1 0 0 0 1 0" rgba="0 0 1 0.2"/>
            <geom type="mesh" mesh="hole71" xyaxes="1 0 0 0 1 0" rgba="0 0 1 0.2"/>
            <geom type="mesh" mesh="hole72" xyaxes="1 0 0 0 1 0" rgba="0 0 1 0.2"/>
            <geom type="mesh" mesh="hole73" xyaxes="1 0 0 0 1 0" rgba="0 0 1 0.2"/>

        </body>

        <body name="peg" pos="0 0 0">
            <inertial pos="0 0 0" mass="1.0" diaginertia="0.1 0.1 0.1" />

            <site name="peg/origin" pos="0 0 0" />
            <site name="peg/sensor" pos="0 0 0" />

            <geom type="mesh" mesh="peg1" xyaxes="1 0 0 0 1 0" rgba="1 0 0 0.8"/>
            <geom type="mesh" mesh="peg2" xyaxes="1 0 0 0 1 0" rgba="1 0 0 0.8"/>
            <geom type="mesh" mesh="peg3" xyaxes="1 0 0 0 1 0" rgba="1 0 0 0.8"/>

            <joint name="trans_x" type="slide" axis="1 0 0" limited="false"/>
            <joint name="trans_y" type="slide" axis="0 1 0" limited="false"/>
            <joint name="trans_z" type="slide" axis="0 0 1" limited="false"/>
            <joint name="hinge_x" type="hinge" axis="1 0 0" limited="false"/>
            <joint name="hinge_y" type="hinge" axis="0 1 0" limited="false"/>
            <joint name="hinge_z" type="hinge" axis="0 0 1" limited="false"/>
        </body>

    </worldbody>

    <actuator>
        <position name="x" forcelimited="true" forcerange="-20 20" joint="trans_x" kp="100000" kv="100" />
        <position name="y" forcelimited="true" forcerange="-20 20" joint="trans_y" kp="100000" kv="100" />
        <position name="z" forcelimited="true" forcerange="-20 20" joint="trans_z" kp="100000" kv="100" />
        <position name="rx" forcelimited="true" forcerange="-5 5" joint="hinge_x" kp="50" kv="5" />
        <position name="ry" forcelimited="true" forcerange="-5 5" joint="hinge_y" kp="50" kv="5"/>
        <position name="rz" forcelimited="true" forcerange="-5 5" joint="hinge_z" kp="50" kv="5"/>
    </actuator> 

    <sensor>
        <force name="force_sensor" site="peg/sensor" />
        <torque name="torque_sensor" site="peg/sensor" />
        <framepos name="peg_pos" objtype="site" objname="peg/origin"/>
        <framequat name="peg_quat" objtype="site" objname="peg/origin"/>
    </sensor>
</mujoco>