<mujoco>
    <option timestep=".001">
        <flag energy="enable" contact="enable" override="enable"/>
    </option>

    <default>
        <default class="hole_geom">
            <geom xyaxes="1 0 0 0 1 0" rgba="0 0 1 0.2"/>
        </default>
        <site size="0.0002" />
        <geom friction="10000" />
    </default>

    <visual>
        <global offwidth="960" offheight="720"/>
    </visual>

    <asset>
        <mesh name="peg1" file="../asset/extrusion/extrusion_peg/decomposition/Body1.stl" />
        <mesh name="peg2" file="../asset/extrusion/extrusion_peg/decomposition/Body2.stl" />
        <mesh name="peg3" file="../asset/extrusion/extrusion_peg/decomposition/Body3.stl" />
        <mesh name="peg4" file="../asset/extrusion/extrusion_peg/decomposition/Body4.stl" />
        <mesh name="peg5" file="../asset/extrusion/extrusion_peg/decomposition/Body5.stl" />
        <mesh name="peg6" file="../asset/extrusion/extrusion_peg/decomposition/Body6.stl" />
        <mesh name="peg7" file="../asset/extrusion/extrusion_peg/decomposition/Body7.stl" />
        <mesh name="peg8" file="../asset/extrusion/extrusion_peg/decomposition/Body8.stl" />
        <mesh name="peg9" file="../asset/extrusion/extrusion_peg/decomposition/Body9.stl" />
        <mesh name="peg10" file="../asset/extrusion/extrusion_peg/decomposition/Body10.stl" />
        <mesh name="peg11" file="../asset/extrusion/extrusion_peg/decomposition/Body11.stl" />
        <mesh name="peg12" file="../asset/extrusion/extrusion_peg/decomposition/Body12.stl" />
        <mesh name="peg13" file="../asset/extrusion/extrusion_peg/decomposition/Body13.stl" />
        <mesh name="peg14" file="../asset/extrusion/extrusion_peg/decomposition/Body14.stl" />
        <mesh name="peg15" file="../asset/extrusion/extrusion_peg/decomposition/Body15.stl" />
        <mesh name="peg16" file="../asset/extrusion/extrusion_peg/decomposition/Body16.stl" />
        <mesh name="peg17" file="../asset/extrusion/extrusion_peg/decomposition/Body17.stl" />
        <mesh name="peg18" file="../asset/extrusion/extrusion_peg/decomposition/Body18.stl" />
        <mesh name="peg19" file="../asset/extrusion/extrusion_peg/decomposition/Body19.stl" />
        <mesh name="peg20" file="../asset/extrusion/extrusion_peg/decomposition/Body20.stl" />
        <mesh name="peg21" file="../asset/extrusion/extrusion_peg/decomposition/Body21.stl" />
        <mesh name="peg22" file="../asset/extrusion/extrusion_peg/decomposition/Body22.stl" />
        <mesh name="peg23" file="../asset/extrusion/extrusion_peg/decomposition/Body23.stl" />
        <mesh name="peg24" file="../asset/extrusion/extrusion_peg/decomposition/Body24.stl" />
        <mesh name="peg25" file="../asset/extrusion/extrusion_peg/decomposition/Body25.stl" />
        <mesh name="peg26" file="../asset/extrusion/extrusion_peg/decomposition/Body26.stl" />
        <mesh name="peg27" file="../asset/extrusion/extrusion_peg/decomposition/Body27.stl" />
        <mesh name="peg28" file="../asset/extrusion/extrusion_peg/decomposition/Body28.stl" />
        <mesh name="peg29" file="../asset/extrusion/extrusion_peg/decomposition/Body29.stl" />
        <mesh name="peg30" file="../asset/extrusion/extrusion_peg/decomposition/Body30.stl" />
        <mesh name="peg31" file="../asset/extrusion/extrusion_peg/decomposition/Body31.stl" />
        <mesh name="peg32" file="../asset/extrusion/extrusion_peg/decomposition/Body32.stl" />
        <mesh name="peg33" file="../asset/extrusion/extrusion_peg/decomposition/Body33.stl" />
        
        <mesh name="hole1" file="../asset/extrusion/extrusion_hole/decomposition/Body1.stl" />
        <mesh name="hole2" file="../asset/extrusion/extrusion_hole/decomposition/Body2.stl" />
        <mesh name="hole3" file="../asset/extrusion/extrusion_hole/decomposition/Body3.stl" />
        <mesh name="hole4" file="../asset/extrusion/extrusion_hole/decomposition/Body4.stl" />
        <mesh name="hole5" file="../asset/extrusion/extrusion_hole/decomposition/Body5.stl" />
        <mesh name="hole6" file="../asset/extrusion/extrusion_hole/decomposition/Body6.stl" />
        <mesh name="hole7" file="../asset/extrusion/extrusion_hole/decomposition/Body7.stl" />
        <mesh name="hole8" file="../asset/extrusion/extrusion_hole/decomposition/Body8.stl" />
        <mesh name="hole9" file="../asset/extrusion/extrusion_hole/decomposition/Body9.stl" />
        <mesh name="hole10" file="../asset/extrusion/extrusion_hole/decomposition/Body10.stl" />
        <mesh name="hole11" file="../asset/extrusion/extrusion_hole/decomposition/Body11.stl" />
        <mesh name="hole12" file="../asset/extrusion/extrusion_hole/decomposition/Body12.stl" />
        <mesh name="hole13" file="../asset/extrusion/extrusion_hole/decomposition/Body13.stl" />
        <mesh name="hole14" file="../asset/extrusion/extrusion_hole/decomposition/Body14.stl" />
        <mesh name="hole15" file="../asset/extrusion/extrusion_hole/decomposition/Body15.stl" />
        <mesh name="hole16" file="../asset/extrusion/extrusion_hole/decomposition/Body16.stl" />
        <mesh name="hole17" file="../asset/extrusion/extrusion_hole/decomposition/Body17.stl" />
        <mesh name="hole18" file="../asset/extrusion/extrusion_hole/decomposition/Body18.stl" />
        <mesh name="hole19" file="../asset/extrusion/extrusion_hole/decomposition/Body19.stl" />
        <mesh name="hole20" file="../asset/extrusion/extrusion_hole/decomposition/Body20.stl" />
        <mesh name="hole21" file="../asset/extrusion/extrusion_hole/decomposition/Body21.stl" />
        <mesh name="hole22" file="../asset/extrusion/extrusion_hole/decomposition/Body22.stl" />
        <mesh name="hole23" file="../asset/extrusion/extrusion_hole/decomposition/Body23.stl" />
        <mesh name="hole24" file="../asset/extrusion/extrusion_hole/decomposition/Body24.stl" />
        <mesh name="hole25" file="../asset/extrusion/extrusion_hole/decomposition/Body25.stl" />
        <mesh name="hole26" file="../asset/extrusion/extrusion_hole/decomposition/Body26.stl" />
        <mesh name="hole27" file="../asset/extrusion/extrusion_hole/decomposition/Body27.stl" />
        <mesh name="hole28" file="../asset/extrusion/extrusion_hole/decomposition/Body28.stl" />
        <mesh name="hole29" file="../asset/extrusion/extrusion_hole/decomposition/Body29.stl" />
        <mesh name="hole30" file="../asset/extrusion/extrusion_hole/decomposition/Body30.stl" />
        <mesh name="hole31" file="../asset/extrusion/extrusion_hole/decomposition/Body31.stl" />
        <mesh name="hole32" file="../asset/extrusion/extrusion_hole/decomposition/Body32.stl" />
        <mesh name="hole33" file="../asset/extrusion/extrusion_hole/decomposition/Body33.stl" />
        <mesh name="hole34" file="../asset/extrusion/extrusion_hole/decomposition/Body34.stl" />

    </asset>

    <worldbody>
        <site name="world" pos="0 0 0" size="0.0001" />
        
        <light name="top-light" pos="0.0 0.0 0.5" mode="targetbodycom" target="peg" castshadow="false" ambient=".8 .8 .8" />

        <body name="hole" pos="0 0 0">

            <camera name="track" mode="track" pos="-0.050 -0.050 0.025" euler="60 -45 -30" fovy="69.4"/>

            <inertial pos="0 0 0" mass="0.1" diaginertia="0.1 0.1 0.1" />

            <geom type="mesh" mesh="hole1" xyaxes="1 0 0 0 1 0" rgba="0 0 1 0.2"/>
            <geom type="mesh" mesh="hole2" xyaxes="1 0 0 0 1 0" rgba="0 0 1 0.2"/>
            <geom type="mesh" mesh="hole3" xyaxes="1 0 0 0 1 0" rgba="0 0 1 0.2"/>
            <geom type="mesh" mesh="hole4" xyaxes="1 0 0 0 1 0" rgba="0 0 1 0.2"/>
            <geom type="mesh" mesh="hole5" xyaxes="1 0 0 0 1 0" rgba="0 0 1 0.2"/>
            <geom type="mesh" mesh="hole6" xyaxes="1 0 0 0 1 0" rgba="0 0 1 0.2"/>
            <geom type="mesh" mesh="hole7" xyaxes="1 0 0 0 1 0" rgba="0 0 1 0.2"/>
            <geom type="mesh" mesh="hole8" xyaxes="1 0 0 0 1 0" rgba="0 0 1 0.2"/>
            <geom type="mesh" mesh="hole9" xyaxes="1 0 0 0 1 0" rgba="0 0 1 0.2"/>
            <geom type="mesh" mesh="hole10" xyaxes="1 0 0 0 1 0" rgba="0 0 1 0.2"/>
            <geom type="mesh" mesh="hole11" xyaxes="1 0 0 0 1 0" rgba="0 0 1 0.2"/>
            <geom type="mesh" mesh="hole12" xyaxes="1 0 0 0 1 0" rgba="0 0 1 0.2"/>
            <geom type="mesh" mesh="hole13" xyaxes="1 0 0 0 1 0" rgba="0 0 1 0.2"/>
            <geom type="mesh" mesh="hole14" xyaxes="1 0 0 0 1 0" rgba="0 0 1 0.2"/>
            <geom type="mesh" mesh="hole15" xyaxes="1 0 0 0 1 0" rgba="0 0 1 0.2"/>
            <geom type="mesh" mesh="hole16" xyaxes="1 0 0 0 1 0" rgba="0 0 1 0.2"/>
            <geom type="mesh" mesh="hole17" xyaxes="1 0 0 0 1 0" rgba="0 0 1 0.2"/>
            <geom type="mesh" mesh="hole18" xyaxes="1 0 0 0 1 0" rgba="0 0 1 0.2"/>
            <geom type="mesh" mesh="hole19" xyaxes="1 0 0 0 1 0" rgba="0 0 1 0.2"/>
            <geom type="mesh" mesh="hole20" xyaxes="1 0 0 0 1 0" rgba="0 0 1 0.2"/>
            <geom type="mesh" mesh="hole21" xyaxes="1 0 0 0 1 0" rgba="0 0 1 0.2"/>
            <geom type="mesh" mesh="hole22" xyaxes="1 0 0 0 1 0" rgba="0 0 1 0.2"/>
            <geom type="mesh" mesh="hole23" xyaxes="1 0 0 0 1 0" rgba="0 0 1 0.2"/>
            <geom type="mesh" mesh="hole24" xyaxes="1 0 0 0 1 0" rgba="0 0 1 0.2"/>
            <geom type="mesh" mesh="hole25" xyaxes="1 0 0 0 1 0" rgba="0 0 1 0.2"/>
            <geom type="mesh" mesh="hole26" xyaxes="1 0 0 0 1 0" rgba="0 0 1 0.2"/>
            <geom type="mesh" mesh="hole27" xyaxes="1 0 0 0 1 0" rgba="0 0 1 0.2"/>
            <geom type="mesh" mesh="hole28" xyaxes="1 0 0 0 1 0" rgba="0 0 1 0.2"/>
            <geom type="mesh" mesh="hole29" xyaxes="1 0 0 0 1 0" rgba="0 0 1 0.2"/>
            <geom type="mesh" mesh="hole30" xyaxes="1 0 0 0 1 0" rgba="0 0 1 0.2"/>
            <geom type="mesh" mesh="hole31" xyaxes="1 0 0 0 1 0" rgba="0 0 1 0.2"/>
            <geom type="mesh" mesh="hole32" xyaxes="1 0 0 0 1 0" rgba="0 0 1 0.2"/>
            <geom type="mesh" mesh="hole33" xyaxes="1 0 0 0 1 0" rgba="0 0 1 0.2"/>
            <geom type="mesh" mesh="hole34" xyaxes="1 0 0 0 1 0" rgba="0 0 1 0.2"/>

        </body>

        <body name="peg" pos="0 0 0">
            <inertial pos="0 0 0" mass="1.0" diaginertia="0.1 0.1 0.1" />

            <site name="peg/origin" pos="0 0 0" />
            <site name="peg/sensor" pos="0 0 0" />

            <geom type="mesh" mesh="peg1" xyaxes="1 0 0 0 1 0" rgba="1 0 0 0.8"/>
            <geom type="mesh" mesh="peg2" xyaxes="1 0 0 0 1 0" rgba="1 0 0 0.8"/>
            <geom type="mesh" mesh="peg3" xyaxes="1 0 0 0 1 0" rgba="1 0 0 0.8"/>
            <geom type="mesh" mesh="peg4" xyaxes="1 0 0 0 1 0" rgba="1 0 0 0.8"/>
            <geom type="mesh" mesh="peg5" xyaxes="1 0 0 0 1 0" rgba="1 0 0 0.8"/>
            <geom type="mesh" mesh="peg6" xyaxes="1 0 0 0 1 0" rgba="1 0 0 0.8"/>
            <geom type="mesh" mesh="peg7" xyaxes="1 0 0 0 1 0" rgba="1 0 0 0.8"/>
            <geom type="mesh" mesh="peg8" xyaxes="1 0 0 0 1 0" rgba="1 0 0 0.8"/>
            <geom type="mesh" mesh="peg9" xyaxes="1 0 0 0 1 0" rgba="1 0 0 0.8"/>
            <geom type="mesh" mesh="peg10" xyaxes="1 0 0 0 1 0" rgba="1 0 0 0.8"/>
            <geom type="mesh" mesh="peg11" xyaxes="1 0 0 0 1 0" rgba="1 0 0 0.8"/>
            <geom type="mesh" mesh="peg12" xyaxes="1 0 0 0 1 0" rgba="1 0 0 0.8"/>
            <geom type="mesh" mesh="peg13" xyaxes="1 0 0 0 1 0" rgba="1 0 0 0.8"/>
            <geom type="mesh" mesh="peg14" xyaxes="1 0 0 0 1 0" rgba="1 0 0 0.8"/>
            <geom type="mesh" mesh="peg15" xyaxes="1 0 0 0 1 0" rgba="1 0 0 0.8"/>
            <geom type="mesh" mesh="peg16" xyaxes="1 0 0 0 1 0" rgba="1 0 0 0.8"/>
            <geom type="mesh" mesh="peg17" xyaxes="1 0 0 0 1 0" rgba="1 0 0 0.8"/>
            <geom type="mesh" mesh="peg18" xyaxes="1 0 0 0 1 0" rgba="1 0 0 0.8"/>
            <geom type="mesh" mesh="peg19" xyaxes="1 0 0 0 1 0" rgba="1 0 0 0.8"/>
            <geom type="mesh" mesh="peg20" xyaxes="1 0 0 0 1 0" rgba="1 0 0 0.8"/>
            <geom type="mesh" mesh="peg21" xyaxes="1 0 0 0 1 0" rgba="1 0 0 0.8"/>
            <geom type="mesh" mesh="peg22" xyaxes="1 0 0 0 1 0" rgba="1 0 0 0.8"/>
            <geom type="mesh" mesh="peg23" xyaxes="1 0 0 0 1 0" rgba="1 0 0 0.8"/>
            <geom type="mesh" mesh="peg24" xyaxes="1 0 0 0 1 0" rgba="1 0 0 0.8"/>
            <geom type="mesh" mesh="peg25" xyaxes="1 0 0 0 1 0" rgba="1 0 0 0.8"/>
            <geom type="mesh" mesh="peg26" xyaxes="1 0 0 0 1 0" rgba="1 0 0 0.8"/>
            <geom type="mesh" mesh="peg27" xyaxes="1 0 0 0 1 0" rgba="1 0 0 0.8"/>
            <geom type="mesh" mesh="peg28" xyaxes="1 0 0 0 1 0" rgba="1 0 0 0.8"/>
            <geom type="mesh" mesh="peg29" xyaxes="1 0 0 0 1 0" rgba="1 0 0 0.8"/>
            <geom type="mesh" mesh="peg30" xyaxes="1 0 0 0 1 0" rgba="1 0 0 0.8"/>
            <geom type="mesh" mesh="peg31" xyaxes="1 0 0 0 1 0" rgba="1 0 0 0.8"/>
            <geom type="mesh" mesh="peg32" xyaxes="1 0 0 0 1 0" rgba="1 0 0 0.8"/>
            <geom type="mesh" mesh="peg33" xyaxes="1 0 0 0 1 0" rgba="1 0 0 0.8"/>

            <joint name="trans_x" type="slide" axis="1 0 0" limited="false"/>
            <joint name="trans_y" type="slide" axis="0 1 0" limited="false"/>
            <joint name="trans_z" type="slide" axis="0 0 1" limited="false"/>
            <joint name="hinge_x" type="hinge" axis="1 0 0" limited="false"/>
            <joint name="hinge_y" type="hinge" axis="0 1 0" limited="false"/>
            <joint name="hinge_z" type="hinge" axis="0 0 1" limited="false"/>
        </body>

    </worldbody>

    <actuator>
        <position name="x" forcelimited="true" forcerange="-20 20" joint="trans_x" kp="100000" kv="100" />
        <position name="y" forcelimited="true" forcerange="-20 20" joint="trans_y" kp="100000" kv="100" />
        <position name="z" forcelimited="true" forcerange="-20 20" joint="trans_z" kp="100000" kv="100" />
        <position name="rx" forcelimited="true" forcerange="-5 5" joint="hinge_x" kp="50" kv="5" />
        <position name="ry" forcelimited="true" forcerange="-5 5" joint="hinge_y" kp="50" kv="5"/>
        <position name="rz" forcelimited="true" forcerange="-5 5" joint="hinge_z" kp="50" kv="5"/>
    </actuator> 

    <sensor>
        <force name="force_sensor" site="peg/sensor" />
        <torque name="torque_sensor" site="peg/sensor" />
        <framepos name="peg_pos" objtype="site" objname="peg/origin"/>
        <framequat name="peg_quat" objtype="site" objname="peg/origin"/>
    </sensor>
</mujoco>