<mujoco>
    <option timestep=".001">
        <flag energy="enable" contact="enable"  override="enable"/>
    </option>

    <default>
        <default class="hole_geom">
            <geom xyaxes="1 0 0 0 1 0" rgba="0.15 0.15 0.15 1"/>
        </default>
        <site size="0.0002" />
        <geom friction="5" />
        <!-- <mesh scale="0.001 0.001 0.001"/> -->
    </default>

    <visual>
        <global offwidth="960" offheight="720"/>
    </visual>

    <asset>

        <mesh name="peg1" file="../asset/hex_peg/hex_peg_decomposition/Body1.stl" />
        <mesh name="peg2" file="../asset/hex_peg/hex_peg_decomposition/Body6.stl" />
        <mesh name="peg3" file="../asset/hex_peg/hex_peg_decomposition/Body7.stl" />


        <mesh name="hole1" file="../asset/hex_peg/hex_hole_decomposition/Body1.stl" />
        <mesh name="hole2" file="../asset/hex_peg/hex_hole_decomposition/Body2.stl" />
        <mesh name="hole3" file="../asset/hex_peg/hex_hole_decomposition/Body3.stl" />
        <mesh name="hole4" file="../asset/hex_peg/hex_hole_decomposition/Body4.stl" />
        <mesh name="hole5" file="../asset/hex_peg/hex_hole_decomposition/Body5.stl" />
        <mesh name="hole6" file="../asset/hex_peg/hex_hole_decomposition/Body6.stl" />

        <!-- <texture name="grid" type="2d" builtin="checker" rgb1=".1 .2 .3" rgb2=".2 .3 .4" width="300"
            height="300" mark="none" />
        <material name="grid" texture="grid" texrepeat="6 6" texuniform="true" reflectance=".1" /> -->

        <texture name="grid" type="2d" file="../asset/green_tex.png" />     
        <material name="grid" texture="grid" texrepeat="6 6" texuniform="true" reflectance="0.0" />
    </asset>

    <worldbody>
        <site name="world" pos="0 0 0" size="0.0001" />
        <light name="top-light" pos="0.1 -.2 0.8" mode="targetbodycom" target="peg"
            castshadow="false" ambient=".4 .4 .4" />

        <!-- <camera name="track" mode="fixed" pos="-0.015 .065 .035" xyaxes="-0.67 -0.2 0 0 -0.1 0.2" /> -->

        <geom name="ground" type="plane" pos="0 0 -0.06" size="1 1 0.01" material="grid"
            friction=".1" />

        <body name="hole" pos="0 0 -0.03">
            <inertial pos="0 0 0" mass="0.1" diaginertia="0.1 0.1 0.1" />

            <geom type="mesh" mesh="hole1" class="hole_geom"/>
            <geom type="mesh" mesh="hole2" class="hole_geom"/>
            <geom type="mesh" mesh="hole3" class="hole_geom"/>
            <geom type="mesh" mesh="hole4" class="hole_geom"/>
            <geom type="mesh" mesh="hole5" class="hole_geom"/>
            <geom type="mesh" mesh="hole6" class="hole_geom"/>
        </body>

        <body name="flage" pos="0 0 0"> 

            <site name="peg/external/motor" pos="0 0 0" />

            <camera name="track" mode="track" pos="-0.03 0.0575 -0.098" euler="-60 -30 180" fovy="69.4"/>

            <joint name="trans_x" type="slide" axis="1 0 0" limited="false"/>
            <joint name="trans_y" type="slide" axis="0 1 0" limited="false"/>
            <joint name="trans_z" type="slide" axis="0 0 1" limited="false"/>
            <joint name="hinge_x" type="hinge" axis="1 0 0" limited="false"/>
            <joint name="hinge_y" type="hinge" axis="0 1 0" limited="false"/>
            <joint name="hinge_z" type="hinge" axis="0 0 1" limited="false"/>


            <body name="peg" pos="0 0 -0.0958">

                <inertial pos="-0.00665 0.00795 0.08289" mass="1.41" diaginertia="0.1 0.1 0.1" />

                <site name="peg_hole_inertial" pos="0 0 0" size="0.0001" />
                <site name="peg/origin" pos="0 0 0" />
                <site name="peg/peg" pos="0 0 -0.01" />
                <site name="peg/tip" pos="0 0 -0.035" />
                <!-- <site name="peg/base" pos="0 0 0.01" /> -->
                <!-- <site name="peg/external/ati_sensor" pos="0 0 0.0388" /> -->

                <site name="peg/peg_bottom_1" pos="0.00625 0.010825 -0.035" />
                <site name="peg/peg_bottom_2" pos="0.00625 -0.010825 -0.035" />
                <site name="peg/peg_bottom_3" pos="0.0125 0 -0.035" />
                <site name="peg/peg_bottom_4" pos="-0.0125 0 -0.035" />
                <site name="peg/peg_bottom_5" pos="-0.00625 0.010825 -0.035" />
                <site name="peg/peg_bottom_6" pos="-0.00625 -0.010825 -0.035" />
    
                <geom type="mesh" mesh="peg1" xyaxes="1 0 0 0 -1 0"/>
                <geom type="mesh" mesh="peg2" xyaxes="1 0 0 0 -1 0"/>
                <geom type="mesh" mesh="peg3" xyaxes="1 0 0 0 -1 0"/>
            </body>
        </body>

    </worldbody>

    <custom>
        <numeric name="sites_on_peg_bottom" data="6"/>
    </custom>
    
    <actuator>
        <position name="x" forcelimited="true" forcerange="-20 20" joint="trans_x" kp="3000" kv="50" />
        <position name="y" forcelimited="true" forcerange="-20 20" joint="trans_y" kp="3000" kv="50" />
        <position name="z" forcelimited="true" forcerange="-20 20" joint="trans_z" kp="3000" kv="50" />
        <position name="rx" forcelimited="true" forcerange="-5 5" joint="hinge_x" kp="100" kv="5" />
        <position name="ry" forcelimited="true" forcerange="-5 5" joint="hinge_y" kp="100" kv="5"/>
        <position name="rz" forcelimited="true" forcerange="-5 5" joint="hinge_z" kp="100" kv="5"/>
    </actuator> 


    <sensor>
        <force name="force_sensor" site="peg/external/motor" />
        <torque name="torque_sensor" site="peg/external/motor" />
        <framepos name="peg_pos" objtype="site" objname="peg/peg"/>
        <framequat name="peg_quat" objtype="site" objname="peg/peg"/>
    </sensor>
</mujoco>