<mujoco>
    <option timestep=".001">
        <flag energy="enable" contact="enable" override="enable"/>
    </option>

    <default>
        <default class="hole_geom">
            <geom xyaxes="1 0 0 0 1 0" rgba="0 0 1 0.2"/>
        </default>
        <site size="0.0002" />
        <geom friction="10000" />
    </default>

    <visual>
        <global offwidth="960" offheight="720"/>
    </visual>

    <asset>
        <mesh name="peg1" file="../asset/slotted_circle/slotted_circle_peg/Body1.stl" />
        <mesh name="peg2" file="../asset/slotted_circle/slotted_circle_peg/Body2.stl" />
        <mesh name="peg3" file="../asset/slotted_circle/slotted_circle_peg/Body3.stl" />
        <mesh name="peg4" file="../asset/slotted_circle/slotted_circle_peg/Body4.stl" />
        <mesh name="peg5" file="../asset/slotted_circle/slotted_circle_peg/Body5.stl" />
        <mesh name="peg6" file="../asset/slotted_circle/slotted_circle_peg/Body6.stl" />
        <mesh name="peg7" file="../asset/slotted_circle/slotted_circle_peg/Body7.stl" />
        <mesh name="peg8" file="../asset/slotted_circle/slotted_circle_peg/Body8.stl" />
        <mesh name="peg9" file="../asset/slotted_circle/slotted_circle_peg/Body9.stl" />
        <mesh name="peg10" file="../asset/slotted_circle/slotted_circle_peg/Body10.stl" />
        <mesh name="peg11" file="../asset/slotted_circle/slotted_circle_peg/Body11.stl" />
        <mesh name="peg12" file="../asset/slotted_circle/slotted_circle_peg/Body12.stl" />
        <mesh name="peg13" file="../asset/slotted_circle/slotted_circle_peg/Body13.stl" />
        <mesh name="peg14" file="../asset/slotted_circle/slotted_circle_peg/Body14.stl" />
        <mesh name="peg15" file="../asset/slotted_circle/slotted_circle_peg/Body15.stl" />
        <mesh name="peg16" file="../asset/slotted_circle/slotted_circle_peg/Body16.stl" />
        <mesh name="peg17" file="../asset/slotted_circle/slotted_circle_peg/Body17.stl" />
        <mesh name="peg18" file="../asset/slotted_circle/slotted_circle_peg/Body18.stl" />
        <mesh name="peg19" file="../asset/slotted_circle/slotted_circle_peg/Body19.stl" />
        <mesh name="peg20" file="../asset/slotted_circle/slotted_circle_peg/Body20.stl" />

        <mesh name="hole1" file="../asset/slotted_circle/slotted_circle_hole/Body1.stl" />
        <mesh name="hole2" file="../asset/slotted_circle/slotted_circle_hole/Body2.stl" />
        <mesh name="hole3" file="../asset/slotted_circle/slotted_circle_hole/Body3.stl" />
        <mesh name="hole4" file="../asset/slotted_circle/slotted_circle_hole/Body4.stl" />
        <mesh name="hole5" file="../asset/slotted_circle/slotted_circle_hole/Body5.stl" />
        <mesh name="hole6" file="../asset/slotted_circle/slotted_circle_hole/Body6.stl" />
        <mesh name="hole7" file="../asset/slotted_circle/slotted_circle_hole/Body7.stl" />
        <mesh name="hole8" file="../asset/slotted_circle/slotted_circle_hole/Body8.stl" />
        <mesh name="hole9" file="../asset/slotted_circle/slotted_circle_hole/Body9.stl" />
        <mesh name="hole10" file="../asset/slotted_circle/slotted_circle_hole/Body10.stl" />
        <mesh name="hole11" file="../asset/slotted_circle/slotted_circle_hole/Body11.stl" />
        <mesh name="hole12" file="../asset/slotted_circle/slotted_circle_hole/Body12.stl" />
        <mesh name="hole13" file="../asset/slotted_circle/slotted_circle_hole/Body13.stl" />
        <mesh name="hole14" file="../asset/slotted_circle/slotted_circle_hole/Body14.stl" />
        <mesh name="hole15" file="../asset/slotted_circle/slotted_circle_hole/Body15.stl" />
        <mesh name="hole16" file="../asset/slotted_circle/slotted_circle_hole/Body16.stl" />
        <mesh name="hole17" file="../asset/slotted_circle/slotted_circle_hole/Body17.stl" />
        <mesh name="hole18" file="../asset/slotted_circle/slotted_circle_hole/Body18.stl" />
        <mesh name="hole19" file="../asset/slotted_circle/slotted_circle_hole/Body19.stl" />
        <mesh name="hole20" file="../asset/slotted_circle/slotted_circle_hole/Body20.stl" />
        <mesh name="hole21" file="../asset/slotted_circle/slotted_circle_hole/Body21.stl" />
        <mesh name="hole22" file="../asset/slotted_circle/slotted_circle_hole/Body22.stl" />
        <mesh name="hole23" file="../asset/slotted_circle/slotted_circle_hole/Body23.stl" />
        <mesh name="hole24" file="../asset/slotted_circle/slotted_circle_hole/Body24.stl" />
        <mesh name="hole25" file="../asset/slotted_circle/slotted_circle_hole/Body25.stl" />
        <mesh name="hole26" file="../asset/slotted_circle/slotted_circle_hole/Body26.stl" />
        <mesh name="hole27" file="../asset/slotted_circle/slotted_circle_hole/Body27.stl" />
        <mesh name="hole28" file="../asset/slotted_circle/slotted_circle_hole/Body28.stl" />
        <mesh name="hole29" file="../asset/slotted_circle/slotted_circle_hole/Body29.stl" />
        <mesh name="hole30" file="../asset/slotted_circle/slotted_circle_hole/Body30.stl" />
        <mesh name="hole31" file="../asset/slotted_circle/slotted_circle_hole/Body31.stl" />
        <mesh name="hole32" file="../asset/slotted_circle/slotted_circle_hole/Body32.stl" />
        <mesh name="hole33" file="../asset/slotted_circle/slotted_circle_hole/Body33.stl" />
        <mesh name="hole34" file="../asset/slotted_circle/slotted_circle_hole/Body34.stl" />
        <mesh name="hole35" file="../asset/slotted_circle/slotted_circle_hole/Body35.stl" />
        <mesh name="hole36" file="../asset/slotted_circle/slotted_circle_hole/Body36.stl" />
        <mesh name="hole37" file="../asset/slotted_circle/slotted_circle_hole/Body37.stl" />
        <mesh name="hole38" file="../asset/slotted_circle/slotted_circle_hole/Body38.stl" />
        <mesh name="hole39" file="../asset/slotted_circle/slotted_circle_hole/Body39.stl" />
        <mesh name="hole40" file="../asset/slotted_circle/slotted_circle_hole/Body40.stl" />
        <mesh name="hole41" file="../asset/slotted_circle/slotted_circle_hole/Body41.stl" />
        <mesh name="hole42" file="../asset/slotted_circle/slotted_circle_hole/Body42.stl" />
        <mesh name="hole43" file="../asset/slotted_circle/slotted_circle_hole/Body43.stl" />
        <mesh name="hole44" file="../asset/slotted_circle/slotted_circle_hole/Body44.stl" />
        <mesh name="hole45" file="../asset/slotted_circle/slotted_circle_hole/Body45.stl" />
        <mesh name="hole46" file="../asset/slotted_circle/slotted_circle_hole/Body46.stl" />
        <mesh name="hole47" file="../asset/slotted_circle/slotted_circle_hole/Body47.stl" />
        <mesh name="hole48" file="../asset/slotted_circle/slotted_circle_hole/Body48.stl" />
        <mesh name="hole49" file="../asset/slotted_circle/slotted_circle_hole/Body49.stl" />
        <mesh name="hole50" file="../asset/slotted_circle/slotted_circle_hole/Body50.stl" />
        <mesh name="hole51" file="../asset/slotted_circle/slotted_circle_hole/Body51.stl" />
        <mesh name="hole52" file="../asset/slotted_circle/slotted_circle_hole/Body52.stl" />
        <mesh name="hole53" file="../asset/slotted_circle/slotted_circle_hole/Body53.stl" />
        <mesh name="hole54" file="../asset/slotted_circle/slotted_circle_hole/Body54.stl" />
        <mesh name="hole55" file="../asset/slotted_circle/slotted_circle_hole/Body55.stl" />
        <mesh name="hole56" file="../asset/slotted_circle/slotted_circle_hole/Body56.stl" />
        <mesh name="hole57" file="../asset/slotted_circle/slotted_circle_hole/Body57.stl" />
        <mesh name="hole58" file="../asset/slotted_circle/slotted_circle_hole/Body58.stl" />
        <mesh name="hole59" file="../asset/slotted_circle/slotted_circle_hole/Body59.stl" />
        <mesh name="hole60" file="../asset/slotted_circle/slotted_circle_hole/Body60.stl" />
        <mesh name="hole61" file="../asset/slotted_circle/slotted_circle_hole/Body61.stl" />
        <mesh name="hole62" file="../asset/slotted_circle/slotted_circle_hole/Body62.stl" />
        <mesh name="hole63" file="../asset/slotted_circle/slotted_circle_hole/Body63.stl" />
        <mesh name="hole64" file="../asset/slotted_circle/slotted_circle_hole/Body64.stl" />
        <mesh name="hole65" file="../asset/slotted_circle/slotted_circle_hole/Body65.stl" />
        <mesh name="hole66" file="../asset/slotted_circle/slotted_circle_hole/Body66.stl" />
        <mesh name="hole67" file="../asset/slotted_circle/slotted_circle_hole/Body67.stl" />
        <mesh name="hole68" file="../asset/slotted_circle/slotted_circle_hole/Body68.stl" />
        <mesh name="hole69" file="../asset/slotted_circle/slotted_circle_hole/Body69.stl" />
        <mesh name="hole70" file="../asset/slotted_circle/slotted_circle_hole/Body70.stl" />
        <mesh name="hole71" file="../asset/slotted_circle/slotted_circle_hole/Body71.stl" />
        <mesh name="hole72" file="../asset/slotted_circle/slotted_circle_hole/Body72.stl" />
        <mesh name="hole73" file="../asset/slotted_circle/slotted_circle_hole/Body73.stl" />
        <mesh name="hole74" file="../asset/slotted_circle/slotted_circle_hole/Body74.stl" />
        <mesh name="hole75" file="../asset/slotted_circle/slotted_circle_hole/Body75.stl" />
        <mesh name="hole76" file="../asset/slotted_circle/slotted_circle_hole/Body76.stl" />
    </asset>

    <worldbody>
        <site name="world" pos="0 0 0" size="0.0001" />
        
        <light name="top-light" pos="0.0 0.0 0.5" mode="targetbodycom" target="peg" castshadow="false" ambient=".8 .8 .8" />

        <body name="hole" pos="0 0 0">

            <camera name="track" mode="track" pos="-0.050 -0.050 0.025" euler="60 -45 -30" fovy="69.4"/>
            
            <inertial pos="0 0 0" mass="0.1" diaginertia="0.1 0.1 0.1" />

            <geom type="mesh" mesh="hole1" class="hole_geom"/>
            <geom type="mesh" mesh="hole2" class="hole_geom"/>
            <geom type="mesh" mesh="hole3" class="hole_geom"/>
            <geom type="mesh" mesh="hole4" class="hole_geom"/>
            <geom type="mesh" mesh="hole5" class="hole_geom"/>
            <geom type="mesh" mesh="hole6" class="hole_geom"/>
            <geom type="mesh" mesh="hole7" class="hole_geom"/>
            <geom type="mesh" mesh="hole8" class="hole_geom"/>
            <geom type="mesh" mesh="hole9" class="hole_geom"/>
            <geom type="mesh" mesh="hole10" class="hole_geom"/>
            <geom type="mesh" mesh="hole11" class="hole_geom"/>
            <geom type="mesh" mesh="hole12" class="hole_geom"/>
            <geom type="mesh" mesh="hole13" class="hole_geom"/>
            <geom type="mesh" mesh="hole14" class="hole_geom"/>
            <geom type="mesh" mesh="hole15" class="hole_geom"/>
            <geom type="mesh" mesh="hole16" class="hole_geom"/>
            <geom type="mesh" mesh="hole17" class="hole_geom"/>
            <geom type="mesh" mesh="hole18" class="hole_geom"/>
            <geom type="mesh" mesh="hole19" class="hole_geom"/>
            <geom type="mesh" mesh="hole20" class="hole_geom"/>
            <geom type="mesh" mesh="hole21" class="hole_geom"/>
            <geom type="mesh" mesh="hole22" class="hole_geom"/>
            <geom type="mesh" mesh="hole23" class="hole_geom"/>
            <geom type="mesh" mesh="hole24" class="hole_geom"/>
            <geom type="mesh" mesh="hole25" class="hole_geom"/>
            <geom type="mesh" mesh="hole26" class="hole_geom"/>
            <geom type="mesh" mesh="hole27" class="hole_geom"/>
            <geom type="mesh" mesh="hole28" class="hole_geom"/>
            <geom type="mesh" mesh="hole29" class="hole_geom"/>
            <geom type="mesh" mesh="hole30" class="hole_geom"/>
            <geom type="mesh" mesh="hole31" class="hole_geom"/>
            <geom type="mesh" mesh="hole32" class="hole_geom"/>
            <geom type="mesh" mesh="hole33" class="hole_geom"/>
            <geom type="mesh" mesh="hole34" class="hole_geom"/>
            <geom type="mesh" mesh="hole35" class="hole_geom"/>
            <geom type="mesh" mesh="hole36" class="hole_geom"/>
            <geom type="mesh" mesh="hole37" class="hole_geom"/>
            <geom type="mesh" mesh="hole38" class="hole_geom"/>
            <geom type="mesh" mesh="hole39" class="hole_geom"/>
            <geom type="mesh" mesh="hole40" class="hole_geom"/>
            <geom type="mesh" mesh="hole41" class="hole_geom"/>
            <geom type="mesh" mesh="hole42" class="hole_geom"/>
            <geom type="mesh" mesh="hole43" class="hole_geom"/>
            <geom type="mesh" mesh="hole44" class="hole_geom"/>
            <geom type="mesh" mesh="hole45" class="hole_geom"/>
            <geom type="mesh" mesh="hole46" class="hole_geom"/>
            <geom type="mesh" mesh="hole47" class="hole_geom"/>
            <geom type="mesh" mesh="hole48" class="hole_geom"/>
            <geom type="mesh" mesh="hole49" class="hole_geom"/>
            <geom type="mesh" mesh="hole50" class="hole_geom"/>
            <geom type="mesh" mesh="hole51" class="hole_geom"/>
            <geom type="mesh" mesh="hole52" class="hole_geom"/>
            <geom type="mesh" mesh="hole53" class="hole_geom"/>
            <geom type="mesh" mesh="hole54" class="hole_geom"/>
            <geom type="mesh" mesh="hole55" class="hole_geom"/>
            <geom type="mesh" mesh="hole56" class="hole_geom"/>
            <geom type="mesh" mesh="hole57" class="hole_geom"/>
            <geom type="mesh" mesh="hole58" class="hole_geom"/>
            <geom type="mesh" mesh="hole59" class="hole_geom"/>
            <geom type="mesh" mesh="hole60" class="hole_geom"/>
            <geom type="mesh" mesh="hole61" class="hole_geom"/>
            <geom type="mesh" mesh="hole62" class="hole_geom"/>
            <geom type="mesh" mesh="hole63" class="hole_geom"/>
            <geom type="mesh" mesh="hole64" class="hole_geom"/>
            <geom type="mesh" mesh="hole65" class="hole_geom"/>
            <geom type="mesh" mesh="hole66" class="hole_geom"/>
            <geom type="mesh" mesh="hole67" class="hole_geom"/>
            <geom type="mesh" mesh="hole68" class="hole_geom"/>
            <geom type="mesh" mesh="hole69" class="hole_geom"/>
            <geom type="mesh" mesh="hole70" class="hole_geom"/>
            <geom type="mesh" mesh="hole71" class="hole_geom"/>
            <geom type="mesh" mesh="hole72" class="hole_geom"/>
            <geom type="mesh" mesh="hole73" class="hole_geom"/>
            <geom type="mesh" mesh="hole74" class="hole_geom"/>
            <geom type="mesh" mesh="hole75" class="hole_geom"/>
            <geom type="mesh" mesh="hole76" class="hole_geom"/>

        </body>

        <body name="peg" pos="0 0 0">
            <inertial pos="0 0 0" mass="1.0" diaginertia="0.1 0.1 0.1" />

            <site name="peg/origin" pos="0 0 0" />
            <site name="peg/sensor" pos="0 0 0" />

            <geom type="mesh" mesh="peg1" xyaxes="1 0 0 0 1 0" rgba="1 0 0 0.8"/>
            <geom type="mesh" mesh="peg2" xyaxes="1 0 0 0 1 0" rgba="1 0 0 0.8"/>
            <geom type="mesh" mesh="peg3" xyaxes="1 0 0 0 1 0" rgba="1 0 0 0.8"/>
            <geom type="mesh" mesh="peg4" xyaxes="1 0 0 0 1 0" rgba="1 0 0 0.8"/>
            <geom type="mesh" mesh="peg5" xyaxes="1 0 0 0 1 0" rgba="1 0 0 0.8"/>
            <geom type="mesh" mesh="peg6" xyaxes="1 0 0 0 1 0" rgba="1 0 0 0.8"/>
            <geom type="mesh" mesh="peg7" xyaxes="1 0 0 0 1 0" rgba="1 0 0 0.8"/>
            <geom type="mesh" mesh="peg8" xyaxes="1 0 0 0 1 0" rgba="1 0 0 0.8"/>
            <geom type="mesh" mesh="peg9" xyaxes="1 0 0 0 1 0" rgba="1 0 0 0.8"/>
            <geom type="mesh" mesh="peg10" xyaxes="1 0 0 0 1 0" rgba="1 0 0 0.8"/>
            <geom type="mesh" mesh="peg11" xyaxes="1 0 0 0 1 0" rgba="1 0 0 0.8"/>
            <geom type="mesh" mesh="peg12" xyaxes="1 0 0 0 1 0" rgba="1 0 0 0.8"/>
            <geom type="mesh" mesh="peg13" xyaxes="1 0 0 0 1 0" rgba="1 0 0 0.8"/>
            <geom type="mesh" mesh="peg14" xyaxes="1 0 0 0 1 0" rgba="1 0 0 0.8"/>
            <geom type="mesh" mesh="peg15" xyaxes="1 0 0 0 1 0" rgba="1 0 0 0.8"/>
            <geom type="mesh" mesh="peg16" xyaxes="1 0 0 0 1 0" rgba="1 0 0 0.8"/>
            <geom type="mesh" mesh="peg17" xyaxes="1 0 0 0 1 0" rgba="1 0 0 0.8"/>
            <geom type="mesh" mesh="peg18" xyaxes="1 0 0 0 1 0" rgba="1 0 0 0.8"/>
            <geom type="mesh" mesh="peg19" xyaxes="1 0 0 0 1 0" rgba="1 0 0 0.8"/>
            <geom type="mesh" mesh="peg20" xyaxes="1 0 0 0 1 0" rgba="1 0 0 0.8"/>
           
            <joint name="trans_x" type="slide" axis="1 0 0" limited="false"/>
            <joint name="trans_y" type="slide" axis="0 1 0" limited="false"/>
            <joint name="trans_z" type="slide" axis="0 0 1" limited="false"/>
            <joint name="hinge_x" type="hinge" axis="1 0 0" limited="false"/>
            <joint name="hinge_y" type="hinge" axis="0 1 0" limited="false"/>
            <joint name="hinge_z" type="hinge" axis="0 0 1" limited="false"/>
        </body>

    </worldbody>

    <actuator>
        <position name="x" forcelimited="true" forcerange="-20 20" joint="trans_x" kp="100000" kv="100" />
        <position name="y" forcelimited="true" forcerange="-20 20" joint="trans_y" kp="100000" kv="100" />
        <position name="z" forcelimited="true" forcerange="-20 20" joint="trans_z" kp="100000" kv="100" />
        <position name="rx" forcelimited="true" forcerange="-5 5" joint="hinge_x" kp="50" kv="5" />
        <position name="ry" forcelimited="true" forcerange="-5 5" joint="hinge_y" kp="50" kv="5"/>
        <position name="rz" forcelimited="true" forcerange="-5 5" joint="hinge_z" kp="50" kv="5"/>
    </actuator> 

    <sensor>
        <force name="force_sensor" site="peg/sensor" />
        <torque name="torque_sensor" site="peg/sensor" />
        <framepos name="peg_pos" objtype="site" objname="peg/origin"/>
        <framequat name="peg_quat" objtype="site" objname="peg/origin"/>
    </sensor>
</mujoco>